export class AppError extends Error {
  constructor(
    message: string,
    public code: string,
    public statusCode?: number,
  ) {
    super(message)
    this.name = 'AppError'
    Error.captureStackTrace(this, this.constructor)
  }
}

export class ValidationError extends AppError {
  constructor(message: string) {
    super(message, 'VALIDATION_ERROR', 400)
    this.name = 'ValidationError'
  }
}

export class AuthenticationError extends AppError {
  constructor(message: string = 'Authentication failed') {
    super(message, 'AUTHENTICATION_ERROR', 401)
    this.name = 'AuthenticationError'
  }
}

export class AuthorizationError extends AppError {
  constructor(message: string = 'Access denied') {
    super(message, 'AUTHORIZATION_ERROR', 403)
    this.name = 'AuthorizationError'
  }
}

export class NotFoundError extends AppError {
  constructor(resource: string) {
    super(`${resource} not found`, 'NOT_FOUND', 404)
    this.name = 'NotFoundError'
  }
}

export class ConflictError extends AppError {
  constructor(message: string) {
    super(message, 'CONFLICT', 409)
    this.name = 'ConflictError'
  }
}

export const isAppError = (error: unknown): error is AppError => {
  return error instanceof AppError
}

export const getErrorMessage = (error: unknown): string => {
  if (error instanceof Error) {
    return error.message
  }
  if (typeof error === 'string') {
    return error
  }
  return 'An unexpected error occurred'
}